Workbook
Name mapGrupoStatus: Parametros!$M$4:$N$12

Sheet Dashboard
B2: Controle de Devolução de Peças (RPTG) — Painel de Controle
B3: ="Base de demonstração com "&ROWS(tblBase[Chamado])&" registros fictícios · atualizado em "&DAY(TODAY())&"/"&MONTH(TODAY())&"/"&YEAR(TODAY())
F4: Grupo | G4: Itens
B5: Itens totais | C5: =SUM(tblBase[QTD]) | F5: Concluído | G5: =SUMIFS(tblBase[QTD],tblBase[Grupo_Status],$F5)
B6: Itens devolvidos | C6: =SUMIFS(tblBase[QTD],tblBase[Grupo_Status],"Concluído") | F6: Em andamento | G6: =SUMIFS(tblBase[QTD],tblBase[Grupo_Status],$F6)
B7: % devolvido | C7: =IFERROR(C6/C5,0) | F7: Pendente | G7: =SUMIFS(tblBase[QTD],tblBase[Grupo_Status],$F7)
B8: Itens em aberto | C8: =SUMIFS(tblBase[QTD],tblBase[Grupo_Status],"Pendente")+SUMIFS(tblBase[QTD],tblBase[Grupo_Status],"Em andamento") | F8: Perda / Débito | G8: =SUMIFS(tblBase[QTD],tblBase[Grupo_Status],$F8)
B9: Valor total debitável | C9: =SUM(tblBase[Valor_Total]) | F9: Não aplicável | G9: =SUMIFS(tblBase[QTD],tblBase[Grupo_Status],$F9)
B10: Valor em risco (em aberto) | C10: =SUMIFS(tblBase[Valor_Total],tblBase[Grupo_Status],"Pendente")+SUMIFS(tblBase[Valor_Total],tblBase[Grupo_Status],"Em andamento")
B11: Valor já debitado do STA | C11: =SUMIFS(tblBase[Valor_Total],tblBase[Status],"Debitar do STA")
B12: Aging médio dos pendentes (dias) | C12: =IFERROR(AVERAGE(tblBase[Dias_Em_Aberto]),0)
B13: STAs com itens em aberto | C13: =COUNTIF(SendBulkEmails!F2:F61,">0")
B14: Itens sem e-mail de STA | C14: =COUNTIF(tblBase[Email_STA],"")
B17: Como usar
B18: 1. Lance ou cole novos dados apenas na aba Base_RPTG (tabela tblBase). Todo o resto se atualiza sozinho.
B19: 1a. Preencha só as colunas de entrada: Email_STA, Valor_Total, Grupo_Status, Faixa_Aging, Dias_Em_Aberto, Mes, Ano e Status_Rastreio são fórmulas.
B20: 1b. Cadastre a STA na aba STAs (Cód STA + Email) — é de lá que vêm o e-mail e a lista da aba SendBulkEmails.
B21: 2. Status, Transportadora, Coordenador, Tipo e MEI têm lista suspensa (aba Parametros) — evita a mesma informação escrita de formas diferentes.
B22: 3. Grupo_Status agrupa os 9 status em Concluído / Em andamento / Pendente / Perda-Débito / Não aplicável (intervalo nomeado mapGrupoStatus).
B23: 4. Dias_Em_Aberto e Faixa_Aging medem o tempo desde o encerramento do chamado para o que ainda não voltou.
B24: 5. Abas Resumo_* e Aging_Pendentes usam SUMIFS: não precisam de 'Atualizar' como as tabelas dinâmicas.
B25: 6. Qualidade_Dados lista o que foi corrigido na base original e faz checagens ao vivo.
B26: 7. SendBulkEmails tem 1 linha por STA cadastrada, com assunto e corpo por fórmula; as macros VBA (pasta src/) fazem o envio pelo Outlook.
B27: 8. Todos os nomes, e-mails, códigos e valores desta planilha são fictícios.

Sheet Base_RPTG
A1: Email_STA | B1: Chamado | C1: MEI | D1: UF | E1: Coordenador | F1: Contrato | G1: Tipo | H1: Valor_Debito_Unit | I1: Valor_Total | J1: Dta_Encerramento | K1: Data_Validacao | L1: Status | M1: Grupo_Status | N1: Faixa_Aging | O1: Dias_Em_Aberto | P1: Codigo_STA | Q1: STA | R1: Codigo_Peca | S1: Descricao | T1: QTD | U1: NF | V1: Mes | W1: Ano | X1: Transportadora | Y1: Status_Rastreio
A2: =IFERROR(INDEX(STAs!$G$2:$G$61,MATCH(P2,STAs!$F$2:$F$61,0))&"","") | B2: 20006357 | C2: Não | D2: MS | E2: CENTRO OESTE | F2: Cliente C - Misturador | G2: Misturadores | H2: 60 | I2: =IFERROR(T2*H2,0) | J2: 45901 | K2: 45910 | L2: Ok. Devolvida | M2: =IF(L2="","",IFERROR(VLOOKUP(L2,mapGrupoStatus,2,0),"Outros")) | N2: =IF(O2="","",IF(O2<=30,"0-30 dias",IF(O2<=60,"31-60 dias",IF(O2<=90,"61-90 dias","Mais de 90 dias")))) | O2: =IF(OR(M2="Pendente",M2="Em andamento"),IF(J2="","",TODAY()-J2),"") | P2: 10302 | Q2: Ice Tech Express (10302) | R2: PC-0046 | S2: Sensor de nível modelo 02 | T2: 1 | U2: 110 | V2: =IF(J2="","",MONTH(J2)) | W2: =IF(J2="","",YEAR(J2)) | X2: TransNorte | Y2: =IFERROR(INDEX(Rastreio!$H$2:$H$200,MATCH(X2&"|"&U2,Rastreio!$A$2:$A$200,0)),"")
A3: =IFERROR(INDEX(STAs!$G$2:$G$61,MATCH(P3,STAs!$F$2:$F$61,0))&"","") | B3: 20014343 | C3: Não | D3: RJ | E3: SUDESTE RJ e ES | F3: Cliente B - Chopeira | G3: Chopeiras | H3: 85 | I3: =IFERROR(T3*H3,0) | J3: 45901 | L3: Aguardando Transporte | M3: =IF(L3="","",IFERROR(VLOOKUP(L3,mapGrupoStatus,2,0),"Outros")) | N3: =IF(O3="","",IF(O3<=30,"0-30 dias",IF(O3<=60,"31-60 dias",IF(O3<=90,"61-90 dias","Mais de 90 dias")))) | O3: =IF(OR(M3="Pendente",M3="Em andamento"),IF(J3="","",TODAY()-J3),"") | P3: 12811 | Q3: Norte Frio Técnica (12811) | R3: PC-0036 | S3: Válvula extratora modelo 02 | T3: 2 | U3: 129 | V3: =IF(J3="","",MONTH(J3)) | W3: =IF(J3="","",YEAR(J3)) | X3: ViaCargo | Y3: =IFERROR(INDEX(Rastreio!$H$2:$H$200,MATCH(X3&"|"&U3,Rastreio!$A$2:$A$200,0)),"")
A4: =IFERROR(INDEX(STAs!$G$2:$G$61,MATCH(P4,STAs!$F$2:$F$61,0))&"","") | B4: 20000916 | C4: Não | D4: RJ | E4: SUDESTE RJ e ES | F4: Cliente C - Misturador | G4: Chopeiras | H4: 115 | I4: =IFERROR(T4*H4,0) | J4: 45902 | K4: 45926 | L4: Ok. Devolvida | M4: =IF(L4="","",IFERROR(VLOOKUP(L4,mapGrupoStatus,2,0),"Outros")) | N4: =IF(O4="","",IF(O4<=30,"0-30 dias",IF(O4<=60,"31-60 dias",IF(O4<=90,"61-90 dias","Mais de 90 dias")))) | O4: =IF(OR(M4="Pendente",M4="Em andamento"),IF(J4="","",TODAY()-J4),"") | P4: 12336 | Q4: Termotec ME (12336) | R4: PC-0033 | S4: Regulador de pressão modelo 02 | T4: 1 | U4: 100 | V4: =IF(J4="","",MONTH(J4)) | W4: =IF(J4="","",YEAR(J4)) | X4: CargoMax | Y4: =IFERROR(INDEX(Rastreio!$H$2:$H$200,MATCH(X4&"|"&U4,Rastreio!$A$2:$A$200,0)),"")
A5: =IFERROR(INDEX(STAs!$G$2:$G$61,MATCH(P5,STAs!$F$2:$F$61,0))&"","") | B5: 20024969 | C5: Não | D5: MS | E5: CENTRO OESTE | F5: Cliente B - Chopeira | G5: Refrigeradores | H5: 35 | I5: =IFERROR(T5*H5,0) | J5: 45902 | K5: 45961 | L5: Ok. Devolvida | M5: =IF(L5="","",IFERROR(VLOOKUP(L5,mapGrupoStatus,2,0),"Outros")) | N5: =IF(O5="","",IF(O5<=30,"0-30 dias",IF(O5<=60,"31-60 dias",IF(O5<=90,"61-90 dias","Mais de 90 dias")))) | O5: =IF(OR(M5="Pendente",M5="Em andamento"),IF(J5="","",TODAY()-J5),"") | P5: 10302 | Q5: Ice Tech Express (10302) | R5: PC-0016 | S5: Filtro secador modelo 02 | T5: 3 | U5: 146 | V5: =IF(J5="","",MONTH(J5)) | W5: =IF(J5="","",YEAR(J5)) | X5: LogExpress | Y5: =IFERROR(INDEX(Rastreio!$H$2:$H$200,MATCH(X5&"|"&U5,Rastreio!$A$2:$A$200,0)),"")
A6: =IFERROR(INDEX(STAs!$G$2:$G$61,MATCH(P6,STAs!$F$2:$F$61,0))&"","") | B6: 20038511 | C6: Não | D6: MG | E6: SUDESTE MG | F6: Cliente B - Chopeira | G6: Chopeiras | H6: 85 | I6: =IFERROR(T6*H6,0) | J6: 45902 | K6: 45958 | L6: Ok. Devolvida | M6: =IF(L6="","",IFERROR(VLOOKUP(L6,mapGrupoStatus,2,0),"Outros")) | N6: =IF(O6="","",IF(O6<=30,"0-30 dias",IF(O6<=60,"31-60 dias",IF(O6<=90,"61-90 dias","Mais de 90 dias")))) | O6: =IF(OR(M6="Pendente",M6="Em andamento"),IF(J6="","",TODAY()-J6),"") | P6: 12470 | Q6: Cool Service Técnica (12470) | R6: PC-0036 | S6: Válvula extratora modelo 02 | T6: 2 | U6: 158 | V6: =IF(J6="","",MONTH(J6)) | W6: =IF(J6="","",YEAR(J6)) | X6: ViaCargo | Y6: =IFERROR(INDEX(Rastreio!$H$2:$H$200,MATCH(X6&"|"&U6,Rastreio!$A$2:$A$200,0)),"")
A7: =IFERROR(INDEX(STAs!$G$2:$G$61,MATCH(P7,STAs!$F$2:$F$61,0))&"","") | B7: 20003998 | C7: Não | D7: GO | E7: CENTRO OESTE | F7: Cliente A - Refrigerador | G7: Misturadores | H7: 50 | I7: =IFERROR(T7*H7,0) | J7: 45903 | L7: Não Devolve-Norte | M7: =IF(L7="","",IFERROR(VLOOKUP(L7,mapGrupoStatus,2,0),"Outros")) | N7: =IF(O7="","",IF(O7<=30,"0-30 dias",IF(O7<=60,"31-60 dias",IF(O7<=90,"61-90 dias","Mais de 90 dias")))) | O7: =IF(OR(M7="Pendente",M7="Em andamento"),IF(J7="","",TODAY()-J7),"") | P7: 10317 | Q7: Termotec Manutenção (10317) | R7: PC-0044 | S7: Bico dosador modelo 03 | T7: 1 | V7: =IF(J7="","",MONTH(J7)) | W7: =IF(J7="","",YEAR(J7)) | Y7: =IFERROR(INDEX(Rastreio!$H$2:$H$200,MATCH(X7&"|"&U7,Rastreio!$A$2:$A$200,0)),"")
A8: =IFERROR(INDEX(STAs!$G$2:$G$61,MATCH(P8,STAs!$F$2:$F$61,0))&"","") | B8: 20018341 | C8: Não | D8: AP | E8: NORTE | F8: Cliente A - Refrigerador | G8: Misturadores | H8: 60 | I8: =IFERROR(T8*H8,0) | J8: 45903 | K8: 45927 | L8: Ok. Devolvida | M8: =IF(L8="","",IFERROR(VLOOKUP(L8,mapGrupoStatus,2,0),"Outros")) | N8: =IF(O8="","",IF(O8<=30,"0-30 dias",IF(O8<=60,"31-60 dias",IF(O8<=90,"61-90 dias","Mais de 90 dias")))) | O8: =IF(OR(M8="Pendente",M8="Em andamento"),IF(J8="","",TODAY()-J8),"") | P8: 11859 | Q8: Ice Tech Serviços (11859) | R8: PC-0046 | S8: Sensor de nível modelo 02 | T8: 3 | U8: 124 | V8: =IF(J8="","",MONTH(J8)) | W8: =IF(J8="","",YEAR(J8)) | X8: RotaSul | Y8: =IFERROR(INDEX(Rastreio!$H$2:$H$200,MATCH(X8&"|"&U8,Rastreio!$A$2:$A$200,0)),"")
A9: =IFERROR(INDEX(STAs!$G$2:$G$61,MATCH(P9,STAs!$F$2:$F$61,0))&"","") | B9: 20019775 | C9: Não | D9: RS | E9: SUL | F9: Cliente C - Misturador | G9: Refrigeradores | H9: 35 | I9: =IFERROR(T9*H9,0) | J9: 45903 | K9: 45923 | L9: Ok. Devolvida | M9: =IF(L9="","",IFERROR(VLOOKUP(L9,mapGrupoStatus,2,0),"Outros")) | N9: =IF(O9="","",IF(O9<=30,"0-30 dias",IF(O9<=60,"31-60 dias",IF(O9<=90,"61-90 dias","Mais de 90 dias")))) | O9: =IF(OR(M9="Pendente",M9="Em andamento"),IF(J9="","",TODAY()-J9),"") | P9: 11459 | Q9: Frio ME (11459) | R9: PC-0020 | S9: Gaxeta da porta modelo 03 | T9: 1 | U9: 129 | V9: =IF(J9="","",MONTH(J9)) | W9: =IF(J9="","",YEAR(J9)) | X9: EntregaJá | Y9: =IFERROR(INDEX(Rastreio!$H$2:$H$200,MATCH(X9&"|"&U9,Rastreio!$A$2:$A$200,0)),"")
A10: =IFERROR(INDEX(STAs!$G$2:$G$61,MATCH(P10,STAs!$F$2:$F$61,0))&"","") | B10: 20022442 | C10: Não | D10: PI | E10: NORDESTE | F10: Cliente B - Chopeira | G10: Refrigeradores | H10: 65 | I10: =IFERROR(T10*H10,0) | J10: 45903 | K10: 45940 | L10: Ok. Devolvida | M10: =IF(L10="","",IFERROR(VLOOKUP(L10,mapGrupoStatus,2,0),"Outros")) | N10: =IF(O10="","",IF(O10<=30,"0-30 dias",IF(O10<=60,"31-60 dias",IF(O10<=90,"61-90 dias","Mais de 90 dias")))) | O10: =IF(OR(M10="Pendente",M10="Em andamento"),IF(J10="","",TODAY()-J10),"") | P10: 10562 | Q10: Clima & Cia (10562) | R10: PC-0010 | S10: Ventilador modelo 04 | T10: 1 | U10: 133 | V10: =IF(J10="","",MONTH(J10)) | W10: =IF(J10="","",YEAR(J10)) | X10: EntregaJá | Y10: =IFERROR(INDEX(Rastreio!$H$2:$H$200,MATCH(X10&"|"&U10,Rastreio!$A$2:$A$200,0)),"")
A11: =IFERROR(INDEX(STAs!$G$2:$G$61,MATCH(P11,STAs!$F$2:$F$61,0))&"","") | B11: 20026593 | C11: Não | D11: TO | E11: NORTE | F11: Cliente B - Chopeira | G11: Refrigeradores | H11: 315 | I11: =IFERROR(T11*H11,0) | J11: 45903 | L11: Não Devolve-Norte | M11: =IF(L11="","",IFERROR(VLOOKUP(L11,mapGrupoStatus,2,0),"Outros")) | N11: =IF(O11="","",IF(O11<=30,"0-30 dias",IF(O11<=60,"31-60 dias",IF(O11<=90,"61-90 dias","Mais de 90 dias")))) | O11: =IF(OR(M11="Pendente",M11="Em andamento"),IF(J11="","",TODAY()-J11),"") | P11: 10939 | Q11: Zero Grau Manutenção (10939) | R11: PC-0002 | S11: Compressor modelo 02 | T11: 1 | V11: =IF(J11="","",MONTH(J11)) | W11: =IF(J11="","",YEAR(J11)) | Y11: =IFERROR(INDEX(Rastreio!$H$2:$H$200,MATCH(X11&"|"&U11,Rastreio!$A$2:$A$200,0)),"")
A12: =IFERROR(INDEX(STAs!$G$2:$G$61,MATCH(P12,STAs!$F$2:$F$61,0))&"","") | B12: 20035223 | C12: Não | D12: PR | E12: SUL | F12: Cliente C - Misturador | G12: Refrigeradores | H12: 55 | I12: =IFERROR(T12*H12,0) | J12: 45903 | L12: NF Vencida | M12: =IF(L12="","",IFERROR(VLOOKUP(L12,mapGrupoStatus,2,0),"Outros")) | N12: =IF(O12="","",IF(O12<=30,"0-30 dias",IF(O12<=60,"31-60 dias",IF(O12<=90,"61-90 dias","Mais de 90 dias")))) | O12: =IF(OR(M12="Pendente",M12="Em andamento"),IF(J12="","",TODAY()-J12),"") | P12: 12089 | Q12: Termotec Serviços (12089) | R12: PC-0008 | S12: Ventilador modelo 02 | T12: 2 | V12: =IF(J12="","",MONTH(J12)) | W12: =IF(J12="","",YEAR(J12)) | Y12: =IFERROR(INDEX(Rastreio!$H$2:$H$200,MATCH(X12&"|"&U12,Rastreio!$A$2:$A$200,0)),"")
A13: =IFERROR(INDEX(STAs!$G$2:$G$61,MATCH(P13,STAs!$F$2:$F$61,0))&"","") | B13: 20001996 | C13: Não | D13: PE | E13: NORDESTE | F13: Cliente B - Chopeira | G13: Misturadores | H13: 255 | I13: =IFERROR(T13*H13,0) | J13: 45904 | K13: 45922 | L13: Ok. Devolvida | M13: =IF(L13="","",IFERROR(VLOOKUP(L13,mapGrupoStatus,2,0),"Outros")) | N13: =IF(O13="","",IF(O13<=30,"0-30 dias",IF(O13<=60,"31-60 dias",IF(O13<=90,"61-90 dias","Mais de 90 dias")))) | O13: =IF(OR(M13="Pendente",M13="Em andamento"),IF(J13="","",TODAY()-J13),"") | P13: 11352 | Q13: Frio Express (11352) | R13: PC-0039 | S13: Bomba de recirculação modelo 03 | T13: 1 | U13: 101 | V13: =IF(J13="","",MONTH(J13)) | W13: =IF(J13="","",YEAR(J13)) | X13: TransNorte | Y13: =IFERROR(INDEX(Rastreio!$H$2:$H$200,MATCH(X13&"|"&U13,Rastreio!$A$2:$A$200,0)),"")
A14: =IFERROR(INDEX(STAs!$G$2:$G$61,MATCH(P14,STAs!$F$2:$F$61,0))&"","") | B14: 20009837 | C14: Não | D14: PR | E14: SUL | F14: Cliente A - Refrigerador | G14: Chopeiras | H14: 85 | I14: =IFERROR(T14*H14,0) | J14: 45904 | L14: Em transporte | M14: =IF(L14="","",IFERROR(VLOOKUP(L14,mapGrupoStatus,2,0),"Outros")) | N14: =IF(O14="","",IF(O14<=30,"0-30 dias",IF(O14<=60,"31-60 dias",IF(O14<=90,"61-90 dias","Mais de 90 dias")))) | O14: =IF(OR(M14="Pendente",M14="Em andamento"),IF(J14="","",TODAY()-J14),"") | P14: 10504 | Q14: Zero Grau Ltda (10504) | R14: PC-0035 | S14: Válvula extratora modelo 01 | T14: 2 | U14: 117 | V14: =IF(J14="","",MONTH(J14)) | W14: =IF(J14="","",YEAR(J14)) | X14: TransNorte | Y14: =IFERROR(INDEX(Rastreio!$H$2:$H$200,MATCH(X14&"|"&U14,Rastreio!$A$2:$A$200,0)),"")
A15: =IFERROR(INDEX(STAs!$G$2:$G$61,MATCH(P15,STAs!$F$2:$F$61,0))&"","") | B15: 20023917 | C15: Sim | D15: SP | E15: SUDESTE SP | F15: Cliente B - Chopeira | G15: Misturadores | H15: 200 | I15: =IFERROR(T15*H15,0) | J15: 45904 | L15: Aguardando Transporte | M15: =IF(L15="","",IFERROR(VLOOKUP(L15,mapGrupoStatus,2,0),"Outros")) | N15: =IF(O15="","",IF(O15<=30,"0-30 dias",IF(O15<=60,"31-60 dias",IF(O15<=90,"61-90 dias","Mais de 90 dias")))) | O15: =IF(OR(M15="Pendente",M15="Em andamento"),IF(J15="","",TODAY()-J15),"") | P15: 10010 | Q15: Cool Service ME (10010) | R15: PC-0040 | S15: Motor agitador modelo 01 | T15: 1 | U15: 136 | V15: =IF(J15="","",MONTH(J15)) | W15: =IF(J15="","",YEAR(J15)) | X15: EntregaJá | Y15: =IFERROR(INDEX(Rastreio!$H$2:$H$200,MATCH(X15&"|"&U15,Rastreio!$A$2:$A$200,0)),"")
A16: =IFERROR(INDEX(STAs!$G$2:$G$61,MATCH(P16,STAs!$F$2:$F$61,0))&"","") | B16: 20029380 | C16: Não | D16: SP | E16: SUDESTE SP | F16: Cliente B - Chopeira | G16: Chopeiras | H16: 85 | I16: =IFERROR(T16*H16,0) | J16: 45904 | K16: 45961 | L16: Ok. Devolvida | M16: =IF(L16="","",IFERROR(VLOOKUP(L16,mapGrupoStatus,2,0),"Outros")) | N16: =IF(O16="","",IF(O16<=30,"0-30 dias",IF(O16<=60,"31-60 dias",IF(O16<=90,"61-90 dias","Mais de 90 dias")))) | O16: =IF(OR(M16="Pendente",M16="Em andamento"),IF(J16="","",TODAY()-J16),"") | P16: 11710 | Q16: Brisa & Cia (11710) | R16: PC-0035 | S16: Válvula extratora modelo 01 | T16: 2 | U16: 155 | V16: =IF(J16="","",MONTH(J16)) | W16: =IF(J16="","",YEAR(J16)) | X16: LogExpress | Y16: =IFERROR(INDEX(Rastreio!$H$2:$H$200,MATCH(X16&"|"&U16,Rastreio!$A$2:$A$200,0)),"")
A17: =IFERROR(INDEX(STAs!$G$2:$G$61,MATCH(P17,STAs!$F$2:$F$61,0))&"","") | B17: 20032538 | C17: Não | D17: AM | E17: NORTE | F17: Cliente A - Refrigerador | G17: Refrigeradores | H17: 175 | I17: =IFERROR(T17*H17,0) | J17: 45904 | K17: 45939 | L17: Ok. Devolvida | M17: =IF(L17="","",IFERROR(VLOOKUP(L17,mapGrupoStatus,2,0),"Outros")) | N17: =IF(O17="","",IF(O17<=30,"0-30 dias",IF(O17<=60,"31-60 dias",IF(O17<=90,"61-90 dias","Mais de 90 dias")))) | O17: =IF(OR(M17="Pendente",M17="Em andamento"),IF(J17="","",TODAY()-J17),"") | P17: 12269 | Q17: Polar Técnica (12269) | R17: PC-0012 | S17: Placa eletrônica modelo 02 | T17: 1 | U17: 157 | V17: =IF(J17="","",MONTH(J17)) | W17: =IF(J17="","",YEAR(J17)) | X17: RotaSul | Y17: =IFERROR(INDEX(Rastreio!$H$2:$H$200,MATCH(X17&"|"&U17,Rastreio!$A$2:$A$200,0)),"")
A18: =IFERROR(INDEX(STAs!$G$2:$G$61,MATCH(P18,STAs!$F$2:$F$61,0))&"","") | B18: 20035552 | C18: Não | D18: RR | E18: NORTE | F18: Cliente A - Refrigerador | G18: Refrigeradores | H18: 55 | I18: =IFERROR(T18*H18,0) | J18: 45904 | K18: 45961 | L18: Ok. Devolvida | M18: =IF(L18="","",IFERROR(VLOOKUP(L18,mapGrupoStatus,2,0),"Outros")) | N18: =IF(O18="","",IF(O18<=30,"0-30 dias",IF(O18<=60,"31-60 dias",IF(O18<=90,"61-90 dias","Mais de 90 dias")))) | O18: =IF(OR(M18="Pendente",M18="Em andamento"),IF(J18="","",TODAY()-J18),"") | P18: 10468 | Q18: Clima Express (10468) | R18: PC-0007 | S18: Ventilador modelo 01 | T18: 2 | U18: 165 | V18: =IF(J18="","",MONTH(J18)) | W18: =IF(J18="","",YEAR(J18)) | X18: RotaSul | Y18: =IFERROR(INDEX(Rastreio!$H$2:$H$200,MATCH(X18&"|"&U18,Rastreio!$A$2:$A$200,0)),"")
A19: =IFERROR(INDEX(STAs!$G$2:$G$61,MATCH(P19,STAs!$F$2:$F$61,0))&"","") | B19: 20040039 | C19: Não | D19: SP | E19: SUDESTE SP | F19: Cliente A - Refrigerador | G19: Misturadores | H19: 255 | I19: =IFERROR(T19*H19,0) | J19: 45904 | L19: Aguardando devolução | M19: =IF(L19="","",IFERROR(VLOOKUP(L19,mapGrupoStatus,2,0),"Outros")) | N19: =IF(O19="","",IF(O19<=30,"0-30 dias",IF(O19<=60,"31-60 dias",IF(O19<=90,"61-90 dias","Mais de 90 dias")))) | O19: =IF(OR(M19="Pendente",M19="Em andamento"),IF(J19="","",TODAY()-J19),"") | P19: 12901 | Q19: Frio Serviços (12901) | R19: PC-0037 | S19: Bomba de recirculação modelo 01 | T19: 3 | V19: =IF(J19="","",MONTH(J19)) | W19: =IF(J19="","",YEAR(J19)) | Y19: =IFERROR(INDEX(Rastreio!$H$2:$H$200,MATCH(X19&"|"&U19,Rastreio!$A$2:$A$200,0)),"")
A20: =IFERROR(INDEX(STAs!$G$2:$G$61,MATCH(P20,STAs!$F$2:$F$61,0))&"","") | B20: 20040502 | C20: Não | D20: GO | E20: CENTRO OESTE | F20: Cliente B - Chopeira | G20: Refrigeradores | H20: 155 | I20: =IFERROR(T20*H20,0) | J20: 45904 | L20: Não Devolve-Norte | M20: =IF(L20="","",IFERROR(VLOOKUP(L20,mapGrupoStatus,2,0),"Outros")) | N20: =IF(O20="","",IF(O20<=30,"0-30 dias",IF(O20<=60,"31-60 dias",IF(O20<=90,"61-90 dias","Mais de 90 dias")))) | O20: =IF(OR(M20="Pendente",M20="Em andamento"),IF(J20="","",TODAY()-J20),"") | P20: 12007 | Q20: Refrigel Ltda (12007) | R20: PC-0022 | S20: Controlador digital modelo 02 | T20: 1 | V20: =IF(J20="","",MONTH(J20)) | W20: =IF(J20="","",YEAR(J20)) | Y20: =IFERROR(INDEX(Rastreio!$H$2:$H$200,MATCH(X20&"|"&U20,Rastreio!$A$2:$A$200,0)),"")
A21: =IFERROR(INDEX(STAs!$G$2:$G$61,MATCH(P21,STAs!$F$2:$F$61,0))&"","") | B21: 20004072 | C21: Não | D21: MG | E21: SUDESTE MG | F21: Cliente B - Chopeira | G21: Refrigeradores | H21: 45 | I21: =IFERROR(T21*H21,0) | J21: 45905 | K21: 45948 | L21: Ok. Devolvida | M21: =IF(L21="","",IFERROR(VLOOKUP(L21,mapGrupoStatus,2,0),"Outros")) | N21: =IF(O21="","",IF(O21<=30,"0-30 dias",IF(O21<=60,"31-60 dias",IF(O21<=90,"61-90 dias","Mais de 90 dias")))) | O21: =IF(OR(M21="Pendente",M21="Em andamento"),IF(J21="","",TODAY()-J21),"") | P21: 12689 | Q21: Norte Frio Manutenção (12689) | R21: PC-0019 | S21: Gaxeta da porta modelo 02 | T21: 1 | U21: 105 | V21: =IF(J21="","",MONTH(J21)) | W21: =IF(J21="","",YEAR(J21)) | X21: LogExpress | Y21: =IFERROR(INDEX(Rastreio!$H$2:$H$200,MATCH(X21&"|"&U21,Rastreio!$A$2:$A$200,0)),"")
A22: =IFERROR(INDEX(STAs!$G$2:$G$61,MATCH(P22,STAs!$F$2:$F$61,0))&"","") | B22: 20024708 | C22: Não | D22: PA | E22: NORTE | F22: Cliente C - Misturador | G22: Misturadores | H22: 255 | I22: =IFERROR(T22*H22,0) | J22: 45905 | L22: Não Devolve-Norte | M22: =IF(L22="","",IFERROR(VLOOKUP(L22,mapGrupoStatus,2,0),"Outros")) | N22: =IF(O22="","",IF(O22<=30,"0-30 dias",IF(O22<=60,"31-60 dias",IF(O22<=90,"61-90 dias","Mais de 90 dias")))) | O22: =IF(OR(M22="Pendente",M22="Em andamento"),IF(J22="","",TODAY()-J22),"") | P22: 11986 | Q22: Polar Serviços (11986) | R22: PC-0039 | S22: Bomba de recirculação modelo 03 | T22: 2 | V22: =IF(J22="","",MONTH(J22)) | W22: =IF(J22="","",YEAR(J22)) | Y22: =IFERROR(INDEX(Rastreio!$H$2:$H$200,MATCH(X22&"|"&U22,Rastreio!$A$2:$A$200,0)),"")
A23: =IFERROR(INDEX(STAs!$G$2:$G$61,MATCH(P23,STAs!$F$2:$F$61,0))&"","") | B23: 20025192 | C23: Não | D23: RJ | E23: SUDESTE RJ e ES | F23: Cliente B - Chopeira | G23: Refrigeradores | H23: 50 | I23: =IFERROR(T23*H23,0) | J23: 45905 | L23: NPD | M23: =IF(L23="","",IFERROR(VLOOKUP(L23,mapGrupoStatus,2,0),"Outros")) | N23: =IF(O23="","",IF(O23<=30,"0-30 dias",IF(O23<=60,"31-60 dias",IF(O23<=90,"61-90 dias","Mais de 90 dias")))) | O23: =IF(OR(M23="Pendente",M23="Em andamento"),IF(J23="","",TODAY()-J23),"") | P23: 11059 | Q23: Frio Ltda (11059) | R23: PC-0006 | S23: Termostato modelo 03 | T23: 3 | V23: =IF(J23="","",MONTH(J23)) | W23: =IF(J23="","",YEAR(J23)) | Y23: =IFERROR(INDEX(Rastreio!$H$2:$H$200,MATCH(X23&"|"&U23,Rastreio!$A$2:$A$200,0)),"")
A24: =IFERROR(INDEX(STAs!$G$2:$G$61,MATCH(P24,STAs!$F$2:$F$61,0))&"","") | B24: 20025509 | C24: Não | D24: RJ | E24: SUDESTE RJ e ES | F24: Cliente C - Misturador | G24: Refrigeradores | H24: 35 | I24: =IFERROR(T24*H24,0) | J24: 45905 | K24: 45916 | L24: Ok. Devolvida | M24: =IF(L24="","",IFERROR(VLOOKUP(L24,mapGrupoStatus,2,0),"Outros")) | N24: =IF(O24="","",IF(O24<=30,"0-30 dias",IF(O24<=60,"31-60 dias",IF(O24<=90,"61-90 dias","Mais de 90 dias")))) | O24: =IF(OR(M24="Pendente",M24="Em andamento"),IF(J24="","",TODAY()-J24),"") | P24: 12336 | Q24: Termotec ME (12336) | R24: PC-0016 | S24: Filtro secador modelo 02 | T24: 1 | U24: 142 | V24: =IF(J24="","",MONTH(J24)) | W24: =IF(J24="","",YEAR(J24)) | X24: ViaCargo | Y24: =IFERROR(INDEX(Rastreio!$H$2:$H$200,MATCH(X24&"|"&U24,Rastreio!$A$2:$A$200,0)),"")
A25: =IFERROR(INDEX(STAs!$G$2:$G$61,MATCH(P25,STAs!$F$2:$F$61,0))&"","") | B25: 20035873 | C25: Não | D25: MT | E25: CENTRO OESTE | F25: Cliente A - Refrigerador | G25: Refrigeradores | H25: 50 | I25: =IFERROR(T25*H25,0) | J25: 45905 | L25: Debitar do STA | M25: =IF(L25="","",IFERROR(VLOOKUP(L25,mapGrupoStatus,2,0),"Outros")) | N25: =IF(O25="","",IF(O25<=30,"0-30 dias",IF(O25<=60,"31-60 dias",IF(O25<=90,"61-90 dias","Mais de 90 dias")))) | O25: =IF(OR(M25="Pendente",M25="Em andamento"),IF(J25="","",TODAY()-J25),"") | P25: 10227 | Q25: Assistência Técnica ME (10227) | R25: PC-0006 | S25: Termostato modelo 03 | T25: 1 | V25: =IF(J25="","",MONTH(J25)) | W25: =IF(J25="","",YEAR(J25)) | Y25: =IFERROR(INDEX(Rastreio!$H$2:$H$200,MATCH(X25&"|"&U25,Rastreio!$A$2:$A$200,0)),"")
A26: =IFERROR(INDEX(STAs!$G$2:$G$61,MATCH(P26,STAs!$F$2:$F$61,0))&"","") | B26: 20005745 | C26: Não | D26: ES | E26: SUDESTE RJ e ES | F26: Cliente C - Misturador | G26: Chopeiras | H26: 85 | I26: =IFERROR(T26*H26,0) | J26: 45906 | K26: 45925 | L26: Ok. Devolvida | M26: =IF(L26="","",IFERROR(VLOOKUP(L26,mapGrupoStatus,2,0),"Outros")) | N26: =IF(O26="","",IF(O26<=30,"0-30 dias",IF(O26<=60,"31-60 dias",IF(O26<=90,"61-90 dias","Mais de 90 dias")))) | O26: =IF(OR(M26="Pendente",M26="Em andamento"),IF(J26="","",TODAY()-J26),"") | P26: 11099 | Q26: Refrigel Serviços (11099) | R26: PC-0028 | S26: Torneira de chopp modelo 03 | T26: 1 | U26: 107 | V26: =IF(J26="","",MONTH(J26)) | W26: =IF(J26="","",YEAR(J26)) | X26: CargoMax | Y26: =IFERROR(INDEX(Rastreio!$H$2:$H$200,MATCH(X26&"|"&U26,Rastreio!$A$2:$A$200,0)),"")
A27: =IFERROR(INDEX(STAs!$G$2:$G$61,MATCH(P27,STAs!$F$2:$F$61,0))&"","") | B27: 20009956 | C27: Não | D27: SP | E27: SUDESTE SP | F27: Cliente A - Refrigerador | G27: Misturadores | H27: 50 | I27: =IFERROR(T27*H27,0) | J27: 45906 | L27: Em transporte | M27: =IF(L27="","",IFERROR(VLOOKUP(L27,mapGrupoStatus,2,0),"Outros")) | N27: =IF(O27="","",IF(O27<=30,"0-30 dias",IF(O27<=60,"31-60 dias",IF(O27<=90,"61-90 dias","Mais de 90 dias")))) | O27: =IF(OR(M27="Pendente",M27="Em andamento"),IF(J27="","",TODAY()-J27),"") | P27: 12052 | Q27: Brisa Refrigeração (12052) | R27: PC-0047 | S27: Sensor de nível modelo 03 | T27: 1 | U27: 120 | V27: =IF(J27="","",MONTH(J27)) | W27: =IF(J27="","",YEAR(J27)) | X27: CargoMax | Y27: =IFERROR(INDEX(Rastreio!$H$2:$H$200,MATCH(X27&"|"&U27,Rastreio!$A$2:$A$200,0)),"")
A28: =IFERROR(INDEX(STAs!$G$2:$G$61,MATCH(P28,STAs!$F$2:$F$61,0))&"","") | B28: 20012611 | C28: Não | D28: RJ | E28: SUDESTE RJ e ES | F28: Cliente B - Chopeira | G28: Misturadores | H28: 60 | I28: =IFERROR(T28*H28,0) | J28: 45906 | L28: Em andamento | M28: =IF(L28="","",IFERROR(VLOOKUP(L28,mapGrupoStatus,2,0),"Outros")) | N28: =IF(O28="","",IF(O28<=30,"0-30 dias",IF(O28<=60,"31-60 dias",IF(O28<=90,"61-90 dias","Mais de 90 dias")))) | O28: =IF(OR(M28="Pendente",M28="Em andamento"),IF(J28="","",TODAY()-J28),"") | P28: 10676 | Q28: Clima Serviços (10676) | R28: PC-0048 | S28: Sensor de nível modelo 04 | T28: 1 | U28: 124 | V28: =IF(J28="","",MONTH(J28)) | W28: =IF(J28="","",YEAR(J28)) | X28: EntregaJá | Y28: =IFERROR(INDEX(Rastreio!$H$2:$H$200,MATCH(X28&"|"&U28,Rastreio!$A$2:$A$200,0)),"")
A29: =IFERROR(INDEX(STAs!$G$2:$G$61,MATCH(P29,STAs!$F$2:$F$61,0))&"","") | B29: 20021129 | C29: Não | D29: SP | E29: SUDESTE SP | F29: Cliente B - Chopeira | G29: Refrigeradores | H29: 325 | I29: =IFERROR(T29*H29,0) | J29: 45906 | K29: 45912 | L29: Ok. Devolvida | M29: =IF(L29="","",IFERROR(VLOOKUP(L29,mapGrupoStatus,2,0),"Outros")) | N29: =IF(O29="","",IF(O29<=30,"0-30 dias",IF(O29<=60,"31-60 dias",IF(O29<=90,"61-90 dias","Mais de 90 dias")))) | O29: =IF(OR(M29="Pendente",M29="Em andamento"),IF(J29="","",TODAY()-J29),"") | P29: 10538 | Q29: Frio Refrigeração (10538) | R29: PC-0001 | S29: Compressor modelo 01 | T29: 1 | U29: 139 | V29: =IF(J29="","",MONTH(J29)) | W29: =IF(J29="","",YEAR(J29)) | X29: CargoMax | Y29: =IFERROR(INDEX(Rastreio!$H$2:$H$200,MATCH(X29&"|"&U29,Rastreio!$A$2:$A$200,0)),"")
A30: =IFERROR(INDEX(STAs!$G$2:$G$61,MATCH(P30,STAs!$F$2:$F$61,0))&"","") | B30: 20023674 | C30: Não | D30: RR | E30: NORTE | F30: Cliente A - Refrigerador | G30: Refrigeradores | H30: 25 | I30: =IFERROR(T30*H30,0) | J30: 45906 | K30: 45925 | L30: Ok. Devolvida | M30: =IF(L30="","",IFERROR(VLOOKUP(L30,mapGrupoStatus,2,0),"Outros")) | N30: =IF(O30="","",IF(O30<=30,"0-30 dias",IF(O30<=60,"31-60 dias",IF(O30<=90,"61-90 dias","Mais de 90 dias")))) | O30: =IF(OR(M30="Pendente",M30="Em andamento"),IF(J30="","",TODAY()-J30),"") | P30: 12422 | Q30: Assistência Técnica Refrigeração (12422) | R30: PC-0015 | S30: Filtro secador modelo 01 | T30: 1 | U30: 139 | V30: =IF(J30="","",MONTH(J30)) | W30: =IF(J30="","",YEAR(J30)) | X30: RotaSul | Y30: =IFERROR(INDEX(Rastreio!$H$2:$H$200,MATCH(X30&"|"&U30,Rastreio!$A$2:$A$200,0)),"")
A31: =IFERROR(INDEX(STAs!$G$2:$G$61,MATCH(P31,STAs!$F$2:$F$61,0))&"","") | B31: 20023872 | C31: Não | D31: TO | E31: NORTE | F31: Cliente C - Misturador | G31: Chopeiras | H31: 85 | I31: =IFERROR(T31*H31,0) | J31: 45906 | L31: Não Devolve-Norte | M31: =IF(L31="","",IFERROR(VLOOKUP(L31,mapGrupoStatus,2,0),"Outros")) | N31: =IF(O31="","",IF(O31<=30,"0-30 dias",IF(O31<=60,"31-60 dias",IF(O31<=90,"61-90 dias","Mais de 90 dias")))) | O31: =IF(OR(M31="Pendente",M31="Em andamento"),IF(J31="","",TODAY()-J31),"") | P31: 10939 | Q31: Zero Grau Manutenção (10939) | R31: PC-0036 | S31: Válvula extratora modelo 02 | T31: 2 | V31: =IF(J31="","",MONTH(J31)) | W31: =IF(J31="","",YEAR(J31)) | Y31: =IFERROR(INDEX(Rastreio!$H$2:$H$200,MATCH(X31&"|"&U31,Rastreio!$A$2:$A$200,0)),"")
A32: =IFERROR(INDEX(STAs!$G$2:$G$61,MATCH(P32,STAs!$F$2:$F$61,0))&"","") | B32: 20030728 | C32: Não | D32: PA | E32: NORTE | F32: Cliente A - Refrigerador | G32: Refrigeradores | H32: 315 | I32: =IFERROR(T32*H32,0) | J32: 45906 | L32: Não Devolve-Norte | M32: =IF(L32="","",IFERROR(VLOOKUP(L32,mapGrupoStatus,2,0),"Outros")) | N32: =IF(O32="","",IF(O32<=30,"0-30 dias",IF(O32<=60,"31-60 dias",IF(O32<=90,"61-90 dias","Mais de 90 dias")))) | O32: =IF(OR(M32="Pendente",M32="Em andamento"),IF(J32="","",TODAY()-J32),"") | P32: 11986 | Q32: Polar Serviços (11986) | R32: PC-0002 | S32: Compressor modelo 02 | T32: 2 | V32: =IF(J32="","",MONTH(J32)) | W32: =IF(J32="","",YEAR(J32)) | Y32: =IFERROR(INDEX(Rastreio!$H$2:$H$200,MATCH(X32&"|"&U32,Rastreio!$A$2:$A$200,0)),"")
A33: =IFERROR(INDEX(STAs!$G$2:$G$61,MATCH(P33,STAs!$F$2:$F$61,0))&"","") | B33: 20038093 | C33: Não | D33: BA | E33: NORDESTE | F33: Cliente C - Misturador | G33: Misturadores | H33: 50 | I33: =IFERROR(T33*H33,0) | J33: 45906 | K33: 45943 | L33: Ok. Devolvida | M33: =IF(L33="","",IFERROR(VLOOKUP(L33,mapGrupoStatus,2,0),"Outros")) | N33: =IF(O33="","",IF(O33<=30,"0-30 dias",IF(O33<=60,"31-60 dias",IF(O33<=90,"61-90 dias","Mais de 90 dias")))) | O33: =IF(OR(M33="Pendente",M33="Em andamento"),IF(J33="","",TODAY()-J33),"") | P33: 12194 | Q33: Polar & Cia (12194) | R33: PC-0045 | S33: Sensor de nível modelo 01 | T33: 1 | U33: 169 | V33: =IF(J33="","",MONTH(J33)) | W33: =IF(J33="","",YEAR(J33)) | X33: LogExpress | Y33: =IFERROR(INDEX(Rastreio!$H$2:$H$200,MATCH(X33&"|"&U33,Rastreio!$A$2:$A$200,0)),"")
A34: =IFERROR(INDEX(STAs!$G$2:$G$61,MATCH(P34,STAs!$F$2:$F$61,0))&"","") | B34: 20039365 | C34: Não | D34: PI | E34: NORDESTE | F34: Cliente A - Refrigerador | G34: Chopeiras | H34: 115 | I34: =IFERROR(T34*H34,0) | J34: 45906 | L34: NPD | M34: =IF(L34="","",IFERROR(VLOOKUP(L34,mapGrupoStatus,2,0),"Outros")) | N34: =IF(O34="","",IF(O34<=30,"0-30 dias",IF(O34<=60,"31-60 dias",IF(O34<=90,"61-90 dias","Mais de 90 dias")))) | O34: =IF(OR(M34="Pendente",M34="Em andamento"),IF(J34="","",TODAY()-J34),"") | P34: 12936 | Q34: Frigo Técnica (12936) | R34: PC-0033 | S34: Regulador de pressão modelo 02 | T34: 1 | V34: =IF(J34="","",MONTH(J34)) | W34: =IF(J34="","",YEAR(J34)) | Y34: =IFERROR(INDEX(Rastreio!$H$2:$H$200,MATCH(X34&"|"&U34,Rastreio!$A$2:$A$200,0)),"")
A35: =IFERROR(INDEX(STAs!$G$2:$G$61,MATCH(P35,STAs!$F$2:$F$61,0))&"","") | B35: 20005361 | C35: Não | D35: RJ | E35: SUDESTE RJ e ES | F35: Cliente C - Misturador | G35: Refrigeradores | H35: 155 | I35: =IFERROR(T35*H35,0) | J35: 45907 | K35: 45936 | L35: Ok. Devolvida | M35: =IF(L35="","",IFERROR(VLOOKUP(L35,mapGrupoStatus,2,0),"Outros")) | N35: =IF(O35="","",IF(O35<=30,"0-30 dias",IF(O35<=60,"31-60 dias",IF(O35<=90,"61-90 dias","Mais de 90 dias")))) | O35: =IF(OR(M35="Pendente",M35="Em andamento"),IF(J35="","",TODAY()-J35),"") | P35: 12336 | Q35: Termotec ME (12336) | R35: PC-0021 | S35: Controlador digital modelo 01 | T35: 2 | U35: 107 | V35: =IF(J35="","",MONTH(J35)) | W35: =IF(J35="","",YEAR(J35)) | X35: LogExpress | Y35: =IFERROR(INDEX(Rastreio!$H$2:$H$200,MATCH(X35&"|"&U35,Rastreio!$A$2:$A$200,0)),"")
A36: =IFERROR(INDEX(STAs!$G$2:$G$61,MATCH(P36,STAs!$F$2:$F$61,0))&"","") | B36: 20008774 | C36: Não | D36: ES | E36: SUDESTE RJ e ES | F36: Cliente C - Misturador | G36: Refrigeradores | H36: 35 | I36: =IFERROR(T36*H36,0) | J36: 45907 | L36: Em andamento | M36: =IF(L36="","",IFERROR(VLOOKUP(L36,mapGrupoStatus,2,0),"Outros")) | N36: =IF(O36="","",IF(O36<=30,"0-30 dias",IF(O36<=60,"31-60 dias",IF(O36<=90,"61-90 dias","Mais de 90 dias")))) | O36: =IF(OR(M36="Pendente",M36="Em andamento"),IF(J36="","",TODAY()-J36),"") | P36: 11099 | Q36: Refrigel Serviços (11099) | R36: PC-0016 | S36: Filtro secador modelo 02 | T36: 1 | U36: 115 | V36: =IF(J36="","",MONTH(J36)) | W36: =IF(J36="","",YEAR(J36)) | X36: LogExpress | Y36: =IFERROR(INDEX(Rastreio!$H$2:$H$200,MATCH(X36&"|"&U36,Rastreio!$A$2:$A$200,0)),"")
A37: =IFERROR(INDEX(STAs!$G$2:$G$61,MATCH(P37,STAs!$F$2:$F$61,0))&"","") | B37: 20014963 | C37: Não | D37: SP | E37: SUDESTE SP | F37: Cliente B - Chopeira | G37: Refrigeradores | H37: 325 | I37: =IFERROR(T37*H37,0) | J37: 45907 | K37: 45945 | L37: Ok. Devolvida | M37: =IF(L37="","",IFERROR(VLOOKUP(L37,mapGrupoStatus,2,0),"Outros")) | N37: =IF(O37="","",IF(O37<=30,"0-30 dias",IF(O37<=60,"31-60 dias",IF(O37<=90,"61-90 dias","Mais de 90 dias")))) | O37: =IF(OR(M37="Pendente",M37="Em andamento"),IF(J37="","",TODAY()-J37),"") | P37: 12052 | Q37: Brisa Refrigeração (12052) | R37: PC-0001 | S37: Compressor modelo 01 | T37: 1 | U37: 126 | V37: =IF(J37="","",MONTH(J37)) | W37: =IF(J37="","",YEAR(J37)) | X37: LogExpress | Y37: =IFERROR(INDEX(Rastreio!$H$2:$H$200,MATCH(X37&"|"&U37,Rastreio!$A$2:$A$200,0)),"")
A38: =IFERROR(INDEX(STAs!$G$2:$G$61,MATCH(P38,STAs!$F$2:$F$61,0))&"","") | B38: 20030546 | C38: Não | D38: SP | E38: SUDESTE SP | F38: Cliente C - Misturador | G38: Refrigeradores | H38: 30 | I38: =IFERROR(T38*H38,0) | J38: 45907 | L38: Em transporte | M38: =IF(L38="","",IFERROR(VLOOKUP(L38,mapGrupoStatus,2,0),"Outros")) | N38: =IF(O38="","",IF(O38<=30,"0-30 dias",IF(O38<=60,"31-60 dias",IF(O38<=90,"61-90 dias","Mais de 90 dias")))) | O38: =IF(OR(M38="Pendente",M38="Em andamento"),IF(J38="","",TODAY()-J38),"") | P38: 12901 | Q38: Frio Serviços (12901) | R38: PC-0017 | S38: Filtro secador modelo 03 | T38: 1 | U38: 158 | V38: =IF(J38="","",MONTH(J38)) | W38: =IF(J38="","",YEAR(J38)) | X38: LogExpress | Y38: =IFERROR(INDEX(Rastreio!$H$2:$H$200,MATCH(X38&"|"&U38,Rastreio!$A$2:$A$200,0)),"")
A39: =IFERROR(INDEX(STAs!$G$2:$G$61,MATCH(P39,STAs!$F$2:$F$61,0))&"","") | B39: 20031202 | C39: Não | D39: MG | E39: SUDESTE MG | F39: Cliente C - Misturador | G39: Refrigeradores | H39: 55 | I39: =IFERROR(T39*H39,0) | J39: 45907 | K39: 45920 | L39: Ok. Devolvida | M39: =IF(L39="","",IFERROR(VLOOKUP(L39,mapGrupoStatus,2,0),"Outros")) | N39: =IF(O39="","",IF(O39<=30,"0-30 dias",IF(O39<=60,"31-60 dias",IF(O39<=90,"61-90 dias","Mais de 90 dias")))) | O39: =IF(OR(M39="Pendente",M39="Em andamento"),IF(J39="","",TODAY()-J39),"") | P39: 12158 | Q39: Gelo Serviços (12158) | R39: PC-0007 | S39: Ventilador modelo 01 | T39: 1 | U39: 154 | V39: =IF(J39="","",MONTH(J39)) | W39: =IF(J39="","",YEAR(J39)) | X39: CargoMax | Y39: =IFERROR(INDEX(Rastreio!$H$2:$H$200,MATCH(X39&"|"&U39,Rastreio!$A$2:$A$200,0)),"")
A40: =IFERROR(INDEX(STAs!$G$2:$G$61,MATCH(P40,STAs!$F$2:$F$61,0))&"","") | B40: 20036145 | C40: Não | D40: MG | E40: SUDESTE MG | F40: Cliente C - Misturador | G40: Refrigeradores | H40: 40 | I40: =IFERROR(T40*H40,0) | J40: 45907 | L40: Aguardando Transporte | M40: =IF(L40="","",IFERROR(VLOOKUP(L40,mapGrupoStatus,2,0),"Outros")) | N40: =IF(O40="","",IF(O40<=30,"0-30 dias",IF(O40<=60,"31-60 dias",IF(O40<=90,"61-90 dias","Mais de 90 dias")))) | O40: =IF(OR(M40="Pendente",M40="Em andamento"),IF(J40="","",TODAY()-J40),"") | P40: 12689 | Q40: Norte Frio Manutenção (12689) | R40: PC-0005 | S40: Termostato modelo 02 | T40: 1 | U40: 156 | V40: =IF(J40="","",MONTH(J40)) | W40: =IF(J40="","",YEAR(J40)) | X40: ViaCargo | Y40: =IFERROR(INDEX(Rastreio!$H$2:$H$200,MATCH(X40&"|"&U40,Rastreio!$A$2:$A$200,0)),"")
...

Sheet Parametros
A1: Listas oficiais (usadas na validação de dados da Base_RPTG) e configurações das macros
A2: Envio Automático Ativo: | B2: NAO
A3: Dia da Semana (2=Seg..6=Sex, 8=Diário): | B3: 3 | C3: Grupo_Status | E3: Transportadora | G3: Coordenador | I3: Tipo | K3: MEI | M3: Status | N3: Grupo_Status | O3: Configurações usadas pelas macros VBA
A4: Horário de Disparo: | B4: 09:30 | C4: Concluído | E4: LogExpress | G4: CENTRO OESTE | I4: Refrigeradores | K4: Não | M4: Ok. Devolvida | N4: Concluído | O4: CNPJ do tomador do frete (rastreio Braspress) — só números | P4: 00000000000000
A5: Status oficiais: | C5: Em andamento | E5: TransNorte | G5: NORDESTE | I5: Chopeiras | K5: Sim | M5: Em transporte | N5: Em andamento
A6: Aguardando Transporte | C6: Pendente | E6: ViaCargo | G6: NORTE | I6: Misturadores | M6: Em andamento | N6: Em andamento | O6: Caminho da imagem do banner da assinatura (opcional)
A7: Aguardando devolução | C7: Perda / Débito | E7: RotaSul | G7: SUDESTE MG | M7: Aguardando Transporte | N7: Em andamento
A8: Debitar do STA | C8: Não aplicável | E8: CargoMax | G8: SUDESTE RJ e ES | M8: Aguardando devolução | N8: Pendente | O8: Mês de referência do comunicado | P8: 46174
A9: Em andamento | E9: EntregaJá | G9: SUDESTE SP | M9: NF Vencida | N9: Pendente | O9: Link da tabela de códigos | P9: https://exemplo.com.br/tabela-codigos
A10: Em transporte | G10: SUL | M10: Debitar do STA | N10: Perda / Débito | O10: Texto do bloco Atenção! | P10: Caso algum STA esteja com devolução de {MES_REF} pendente, encaminhe a nota até {DATA_NOTA}; peças de {MES_ANT} devem ser enviadas até {DATA_PECAS}.
A11: NF Vencida | M11: Não Devolve-Norte | N11: Não aplicável | O11: CONSULTORES POR REGIÃO (região na coluna O, e-mails em Cc na coluna P)
A12: NPD | M12: NPD | N12: Não aplicável | O12: Sul | P12: consultor.sul1@exemplo.com.br; consultor.sul2@exemplo.com.br
A13: Não Devolve-Norte | O13: Sudeste | P13: consultor.sudeste1@exemplo.com.br; consultor.sudeste2@exemplo.com.br
A14: Ok. Devolvida | O14: Nordeste | P14: consultor.nordeste1@exemplo.com.br
O15: Centro oeste | P15: consultor.co1@exemplo.com.br
O16: Pasta dos PDFs anexados | P16: C:\Comunicados_STAs
O20: E-mail do Financeiro (planilha de débito) | P20: financeiro@exemplo.com.br
O21: Pasta onde salvar a planilha de débito (vazio = pasta desta planilha)
O23: Cobrança semanal - último envio automático
O24: Cobrança automática - dia da semana (1=dom ... 7=sáb) | P24: 3
O25: Cobrança automática - horário | P25: 09:00
O26: Cobrança automática - intervalo em dias | P26: 7

Sheet Resumo_Status_Mes
A1: Itens por status e mês (fórmulas — atualiza sozinho ao editar a Base_RPTG)
A3: Status | B3: 2025-09 | C3: 2025-10 | D3: 2025-11 | E3: 2025-12 | F3: 2026-01 | G3: 2026-02 | H3: 2026-03 | I3: 2026-04 | J3: 2026-05 | K3: 2026-06 | L3: 2026-07 | M3: 2026-08 | N3: 2026-09 | O3: 2026-10 | P3: 2026-11 | Q3: 2026-12 | R3: Total
A4: Aguardando Transporte | B4: =SUMIFS(tblBase[QTD],tblBase[Status],$A4,tblBase[Ano],2025,tblBase[Mes],9) | C4: =SUMIFS(tblBase[QTD],tblBase[Status],$A4,tblBase[Ano],2025,tblBase[Mes],10) | D4: =SUMIFS(tblBase[QTD],tblBase[Status],$A4,tblBase[Ano],2025,tblBase[Mes],11) | E4: =SUMIFS(tblBase[QTD],tblBase[Status],$A4,tblBase[Ano],2025,tblBase[Mes],12) | F4: =SUMIFS(tblBase[QTD],tblBase[Status],$A4,tblBase[Ano],2026,tblBase[Mes],1) | G4: =SUMIFS(tblBase[QTD],tblBase[Status],$A4,tblBase[Ano],2026,tblBase[Mes],2) | H4: =SUMIFS(tblBase[QTD],tblBase[Status],$A4,tblBase[Ano],2026,tblBase[Mes],3) | I4: =SUMIFS(tblBase[QTD],tblBase[Status],$A4,tblBase[Ano],2026,tblBase[Mes],4) | J4: =SUMIFS(tblBase[QTD],tblBase[Status],$A4,tblBase[Ano],2026,tblBase[Mes],5) | K4: =SUMIFS(tblBase[QTD],tblBase[Status],$A4,tblBase[Ano],2026,tblBase[Mes],6) | L4: =SUMIFS(tblBase[QTD],tblBase[Status],$A4,tblBase[Ano],2026,tblBase[Mes],7) | M4: =SUMIFS(tblBase[QTD],tblBase[Status],$A4,tblBase[Ano],2026,tblBase[Mes],8) | N4: =SUMIFS(tblBase[QTD],tblBase[Status],$A4,tblBase[Ano],2026,tblBase[Mes],9) | O4: =SUMIFS(tblBase[QTD],tblBase[Status],$A4,tblBase[Ano],2026,tblBase[Mes],10) | P4: =SUMIFS(tblBase[QTD],tblBase[Status],$A4,tblBase[Ano],2026,tblBase[Mes],11) | Q4: =SUMIFS(tblBase[QTD],tblBase[Status],$A4,tblBase[Ano],2026,tblBase[Mes],12) | R4: =SUM(B4:Q4)
A5: Aguardando devolução | B5: =SUMIFS(tblBase[QTD],tblBase[Status],$A5,tblBase[Ano],2025,tblBase[Mes],9) | C5: =SUMIFS(tblBase[QTD],tblBase[Status],$A5,tblBase[Ano],2025,tblBase[Mes],10) | D5: =SUMIFS(tblBase[QTD],tblBase[Status],$A5,tblBase[Ano],2025,tblBase[Mes],11) | E5: =SUMIFS(tblBase[QTD],tblBase[Status],$A5,tblBase[Ano],2025,tblBase[Mes],12) | F5: =SUMIFS(tblBase[QTD],tblBase[Status],$A5,tblBase[Ano],2026,tblBase[Mes],1) | G5: =SUMIFS(tblBase[QTD],tblBase[Status],$A5,tblBase[Ano],2026,tblBase[Mes],2) | H5: =SUMIFS(tblBase[QTD],tblBase[Status],$A5,tblBase[Ano],2026,tblBase[Mes],3) | I5: =SUMIFS(tblBase[QTD],tblBase[Status],$A5,tblBase[Ano],2026,tblBase[Mes],4) | J5: =SUMIFS(tblBase[QTD],tblBase[Status],$A5,tblBase[Ano],2026,tblBase[Mes],5) | K5: =SUMIFS(tblBase[QTD],tblBase[Status],$A5,tblBase[Ano],2026,tblBase[Mes],6) | L5: =SUMIFS(tblBase[QTD],tblBase[Status],$A5,tblBase[Ano],2026,tblBase[Mes],7) | M5: =SUMIFS(tblBase[QTD],tblBase[Status],$A5,tblBase[Ano],2026,tblBase[Mes],8) | N5: =SUMIFS(tblBase[QTD],tblBase[Status],$A5,tblBase[Ano],2026,tblBase[Mes],9) | O5: =SUMIFS(tblBase[QTD],tblBase[Status],$A5,tblBase[Ano],2026,tblBase[Mes],10) | P5: =SUMIFS(tblBase[QTD],tblBase[Status],$A5,tblBase[Ano],2026,tblBase[Mes],11) | Q5: =SUMIFS(tblBase[QTD],tblBase[Status],$A5,tblBase[Ano],2026,tblBase[Mes],12) | R5: =SUM(B5:Q5)
A6: Debitar do STA | B6: =SUMIFS(tblBase[QTD],tblBase[Status],$A6,tblBase[Ano],2025,tblBase[Mes],9) | C6: =SUMIFS(tblBase[QTD],tblBase[Status],$A6,tblBase[Ano],2025,tblBase[Mes],10) | D6: =SUMIFS(tblBase[QTD],tblBase[Status],$A6,tblBase[Ano],2025,tblBase[Mes],11) | E6: =SUMIFS(tblBase[QTD],tblBase[Status],$A6,tblBase[Ano],2025,tblBase[Mes],12) | F6: =SUMIFS(tblBase[QTD],tblBase[Status],$A6,tblBase[Ano],2026,tblBase[Mes],1) | G6: =SUMIFS(tblBase[QTD],tblBase[Status],$A6,tblBase[Ano],2026,tblBase[Mes],2) | H6: =SUMIFS(tblBase[QTD],tblBase[Status],$A6,tblBase[Ano],2026,tblBase[Mes],3) | I6: =SUMIFS(tblBase[QTD],tblBase[Status],$A6,tblBase[Ano],2026,tblBase[Mes],4) | J6: =SUMIFS(tblBase[QTD],tblBase[Status],$A6,tblBase[Ano],2026,tblBase[Mes],5) | K6: =SUMIFS(tblBase[QTD],tblBase[Status],$A6,tblBase[Ano],2026,tblBase[Mes],6) | L6: =SUMIFS(tblBase[QTD],tblBase[Status],$A6,tblBase[Ano],2026,tblBase[Mes],7) | M6: =SUMIFS(tblBase[QTD],tblBase[Status],$A6,tblBase[Ano],2026,tblBase[Mes],8) | N6: =SUMIFS(tblBase[QTD],tblBase[Status],$A6,tblBase[Ano],2026,tblBase[Mes],9) | O6: =SUMIFS(tblBase[QTD],tblBase[Status],$A6,tblBase[Ano],2026,tblBase[Mes],10) | P6: =SUMIFS(tblBase[QTD],tblBase[Status],$A6,tblBase[Ano],2026,tblBase[Mes],11) | Q6: =SUMIFS(tblBase[QTD],tblBase[Status],$A6,tblBase[Ano],2026,tblBase[Mes],12) | R6: =SUM(B6:Q6)
A7: Em andamento | B7: =SUMIFS(tblBase[QTD],tblBase[Status],$A7,tblBase[Ano],2025,tblBase[Mes],9) | C7: =SUMIFS(tblBase[QTD],tblBase[Status],$A7,tblBase[Ano],2025,tblBase[Mes],10) | D7: =SUMIFS(tblBase[QTD],tblBase[Status],$A7,tblBase[Ano],2025,tblBase[Mes],11) | E7: =SUMIFS(tblBase[QTD],tblBase[Status],$A7,tblBase[Ano],2025,tblBase[Mes],12) | F7: =SUMIFS(tblBase[QTD],tblBase[Status],$A7,tblBase[Ano],2026,tblBase[Mes],1) | G7: =SUMIFS(tblBase[QTD],tblBase[Status],$A7,tblBase[Ano],2026,tblBase[Mes],2) | H7: =SUMIFS(tblBase[QTD],tblBase[Status],$A7,tblBase[Ano],2026,tblBase[Mes],3) | I7: =SUMIFS(tblBase[QTD],tblBase[Status],$A7,tblBase[Ano],2026,tblBase[Mes],4) | J7: =SUMIFS(tblBase[QTD],tblBase[Status],$A7,tblBase[Ano],2026,tblBase[Mes],5) | K7: =SUMIFS(tblBase[QTD],tblBase[Status],$A7,tblBase[Ano],2026,tblBase[Mes],6) | L7: =SUMIFS(tblBase[QTD],tblBase[Status],$A7,tblBase[Ano],2026,tblBase[Mes],7) | M7: =SUMIFS(tblBase[QTD],tblBase[Status],$A7,tblBase[Ano],2026,tblBase[Mes],8) | N7: =SUMIFS(tblBase[QTD],tblBase[Status],$A7,tblBase[Ano],2026,tblBase[Mes],9) | O7: =SUMIFS(tblBase[QTD],tblBase[Status],$A7,tblBase[Ano],2026,tblBase[Mes],10) | P7: =SUMIFS(tblBase[QTD],tblBase[Status],$A7,tblBase[Ano],2026,tblBase[Mes],11) | Q7: =SUMIFS(tblBase[QTD],tblBase[Status],$A7,tblBase[Ano],2026,tblBase[Mes],12) | R7: =SUM(B7:Q7)
A8: Em transporte | B8: =SUMIFS(tblBase[QTD],tblBase[Status],$A8,tblBase[Ano],2025,tblBase[Mes],9) | C8: =SUMIFS(tblBase[QTD],tblBase[Status],$A8,tblBase[Ano],2025,tblBase[Mes],10) | D8: =SUMIFS(tblBase[QTD],tblBase[Status],$A8,tblBase[Ano],2025,tblBase[Mes],11) | E8: =SUMIFS(tblBase[QTD],tblBase[Status],$A8,tblBase[Ano],2025,tblBase[Mes],12) | F8: =SUMIFS(tblBase[QTD],tblBase[Status],$A8,tblBase[Ano],2026,tblBase[Mes],1) | G8: =SUMIFS(tblBase[QTD],tblBase[Status],$A8,tblBase[Ano],2026,tblBase[Mes],2) | H8: =SUMIFS(tblBase[QTD],tblBase[Status],$A8,tblBase[Ano],2026,tblBase[Mes],3) | I8: =SUMIFS(tblBase[QTD],tblBase[Status],$A8,tblBase[Ano],2026,tblBase[Mes],4) | J8: =SUMIFS(tblBase[QTD],tblBase[Status],$A8,tblBase[Ano],2026,tblBase[Mes],5) | K8: =SUMIFS(tblBase[QTD],tblBase[Status],$A8,tblBase[Ano],2026,tblBase[Mes],6) | L8: =SUMIFS(tblBase[QTD],tblBase[Status],$A8,tblBase[Ano],2026,tblBase[Mes],7) | M8: =SUMIFS(tblBase[QTD],tblBase[Status],$A8,tblBase[Ano],2026,tblBase[Mes],8) | N8: =SUMIFS(tblBase[QTD],tblBase[Status],$A8,tblBase[Ano],2026,tblBase[Mes],9) | O8: =SUMIFS(tblBase[QTD],tblBase[Status],$A8,tblBase[Ano],2026,tblBase[Mes],10) | P8: =SUMIFS(tblBase[QTD],tblBase[Status],$A8,tblBase[Ano],2026,tblBase[Mes],11) | Q8: =SUMIFS(tblBase[QTD],tblBase[Status],$A8,tblBase[Ano],2026,tblBase[Mes],12) | R8: =SUM(B8:Q8)
A9: NF Vencida | B9: =SUMIFS(tblBase[QTD],tblBase[Status],$A9,tblBase[Ano],2025,tblBase[Mes],9) | C9: =SUMIFS(tblBase[QTD],tblBase[Status],$A9,tblBase[Ano],2025,tblBase[Mes],10) | D9: =SUMIFS(tblBase[QTD],tblBase[Status],$A9,tblBase[Ano],2025,tblBase[Mes],11) | E9: =SUMIFS(tblBase[QTD],tblBase[Status],$A9,tblBase[Ano],2025,tblBase[Mes],12) | F9: =SUMIFS(tblBase[QTD],tblBase[Status],$A9,tblBase[Ano],2026,tblBase[Mes],1) | G9: =SUMIFS(tblBase[QTD],tblBase[Status],$A9,tblBase[Ano],2026,tblBase[Mes],2) | H9: =SUMIFS(tblBase[QTD],tblBase[Status],$A9,tblBase[Ano],2026,tblBase[Mes],3) | I9: =SUMIFS(tblBase[QTD],tblBase[Status],$A9,tblBase[Ano],2026,tblBase[Mes],4) | J9: =SUMIFS(tblBase[QTD],tblBase[Status],$A9,tblBase[Ano],2026,tblBase[Mes],5) | K9: =SUMIFS(tblBase[QTD],tblBase[Status],$A9,tblBase[Ano],2026,tblBase[Mes],6) | L9: =SUMIFS(tblBase[QTD],tblBase[Status],$A9,tblBase[Ano],2026,tblBase[Mes],7) | M9: =SUMIFS(tblBase[QTD],tblBase[Status],$A9,tblBase[Ano],2026,tblBase[Mes],8) | N9: =SUMIFS(tblBase[QTD],tblBase[Status],$A9,tblBase[Ano],2026,tblBase[Mes],9) | O9: =SUMIFS(tblBase[QTD],tblBase[Status],$A9,tblBase[Ano],2026,tblBase[Mes],10) | P9: =SUMIFS(tblBase[QTD],tblBase[Status],$A9,tblBase[Ano],2026,tblBase[Mes],11) | Q9: =SUMIFS(tblBase[QTD],tblBase[Status],$A9,tblBase[Ano],2026,tblBase[Mes],12) | R9: =SUM(B9:Q9)
A10: NPD | B10: =SUMIFS(tblBase[QTD],tblBase[Status],$A10,tblBase[Ano],2025,tblBase[Mes],9) | C10: =SUMIFS(tblBase[QTD],tblBase[Status],$A10,tblBase[Ano],2025,tblBase[Mes],10) | D10: =SUMIFS(tblBase[QTD],tblBase[Status],$A10,tblBase[Ano],2025,tblBase[Mes],11) | E10: =SUMIFS(tblBase[QTD],tblBase[Status],$A10,tblBase[Ano],2025,tblBase[Mes],12) | F10: =SUMIFS(tblBase[QTD],tblBase[Status],$A10,tblBase[Ano],2026,tblBase[Mes],1) | G10: =SUMIFS(tblBase[QTD],tblBase[Status],$A10,tblBase[Ano],2026,tblBase[Mes],2) | H10: =SUMIFS(tblBase[QTD],tblBase[Status],$A10,tblBase[Ano],2026,tblBase[Mes],3) | I10: =SUMIFS(tblBase[QTD],tblBase[Status],$A10,tblBase[Ano],2026,tblBase[Mes],4) | J10: =SUMIFS(tblBase[QTD],tblBase[Status],$A10,tblBase[Ano],2026,tblBase[Mes],5) | K10: =SUMIFS(tblBase[QTD],tblBase[Status],$A10,tblBase[Ano],2026,tblBase[Mes],6) | L10: =SUMIFS(tblBase[QTD],tblBase[Status],$A10,tblBase[Ano],2026,tblBase[Mes],7) | M10: =SUMIFS(tblBase[QTD],tblBase[Status],$A10,tblBase[Ano],2026,tblBase[Mes],8) | N10: =SUMIFS(tblBase[QTD],tblBase[Status],$A10,tblBase[Ano],2026,tblBase[Mes],9) | O10: =SUMIFS(tblBase[QTD],tblBase[Status],$A10,tblBase[Ano],2026,tblBase[Mes],10) | P10: =SUMIFS(tblBase[QTD],tblBase[Status],$A10,tblBase[Ano],2026,tblBase[Mes],11) | Q10: =SUMIFS(tblBase[QTD],tblBase[Status],$A10,tblBase[Ano],2026,tblBase[Mes],12) | R10: =SUM(B10:Q10)
A11: Não Devolve-Norte | B11: =SUMIFS(tblBase[QTD],tblBase[Status],$A11,tblBase[Ano],2025,tblBase[Mes],9) | C11: =SUMIFS(tblBase[QTD],tblBase[Status],$A11,tblBase[Ano],2025,tblBase[Mes],10) | D11: =SUMIFS(tblBase[QTD],tblBase[Status],$A11,tblBase[Ano],2025,tblBase[Mes],11) | E11: =SUMIFS(tblBase[QTD],tblBase[Status],$A11,tblBase[Ano],2025,tblBase[Mes],12) | F11: =SUMIFS(tblBase[QTD],tblBase[Status],$A11,tblBase[Ano],2026,tblBase[Mes],1) | G11: =SUMIFS(tblBase[QTD],tblBase[Status],$A11,tblBase[Ano],2026,tblBase[Mes],2) | H11: =SUMIFS(tblBase[QTD],tblBase[Status],$A11,tblBase[Ano],2026,tblBase[Mes],3) | I11: =SUMIFS(tblBase[QTD],tblBase[Status],$A11,tblBase[Ano],2026,tblBase[Mes],4) | J11: =SUMIFS(tblBase[QTD],tblBase[Status],$A11,tblBase[Ano],2026,tblBase[Mes],5) | K11: =SUMIFS(tblBase[QTD],tblBase[Status],$A11,tblBase[Ano],2026,tblBase[Mes],6) | L11: =SUMIFS(tblBase[QTD],tblBase[Status],$A11,tblBase[Ano],2026,tblBase[Mes],7) | M11: =SUMIFS(tblBase[QTD],tblBase[Status],$A11,tblBase[Ano],2026,tblBase[Mes],8) | N11: =SUMIFS(tblBase[QTD],tblBase[Status],$A11,tblBase[Ano],2026,tblBase[Mes],9) | O11: =SUMIFS(tblBase[QTD],tblBase[Status],$A11,tblBase[Ano],2026,tblBase[Mes],10) | P11: =SUMIFS(tblBase[QTD],tblBase[Status],$A11,tblBase[Ano],2026,tblBase[Mes],11) | Q11: =SUMIFS(tblBase[QTD],tblBase[Status],$A11,tblBase[Ano],2026,tblBase[Mes],12) | R11: =SUM(B11:Q11)
A12: Ok. Devolvida | B12: =SUMIFS(tblBase[QTD],tblBase[Status],$A12,tblBase[Ano],2025,tblBase[Mes],9) | C12: =SUMIFS(tblBase[QTD],tblBase[Status],$A12,tblBase[Ano],2025,tblBase[Mes],10) | D12: =SUMIFS(tblBase[QTD],tblBase[Status],$A12,tblBase[Ano],2025,tblBase[Mes],11) | E12: =SUMIFS(tblBase[QTD],tblBase[Status],$A12,tblBase[Ano],2025,tblBase[Mes],12) | F12: =SUMIFS(tblBase[QTD],tblBase[Status],$A12,tblBase[Ano],2026,tblBase[Mes],1) | G12: =SUMIFS(tblBase[QTD],tblBase[Status],$A12,tblBase[Ano],2026,tblBase[Mes],2) | H12: =SUMIFS(tblBase[QTD],tblBase[Status],$A12,tblBase[Ano],2026,tblBase[Mes],3) | I12: =SUMIFS(tblBase[QTD],tblBase[Status],$A12,tblBase[Ano],2026,tblBase[Mes],4) | J12: =SUMIFS(tblBase[QTD],tblBase[Status],$A12,tblBase[Ano],2026,tblBase[Mes],5) | K12: =SUMIFS(tblBase[QTD],tblBase[Status],$A12,tblBase[Ano],2026,tblBase[Mes],6) | L12: =SUMIFS(tblBase[QTD],tblBase[Status],$A12,tblBase[Ano],2026,tblBase[Mes],7) | M12: =SUMIFS(tblBase[QTD],tblBase[Status],$A12,tblBase[Ano],2026,tblBase[Mes],8) | N12: =SUMIFS(tblBase[QTD],tblBase[Status],$A12,tblBase[Ano],2026,tblBase[Mes],9) | O12: =SUMIFS(tblBase[QTD],tblBase[Status],$A12,tblBase[Ano],2026,tblBase[Mes],10) | P12: =SUMIFS(tblBase[QTD],tblBase[Status],$A12,tblBase[Ano],2026,tblBase[Mes],11) | Q12: =SUMIFS(tblBase[QTD],tblBase[Status],$A12,tblBase[Ano],2026,tblBase[Mes],12) | R12: =SUM(B12:Q12)

Sheet Resumo_Transportadora
A1: Desempenho por transportadora
A2: Digite uma nova categoria nas linhas em branco no fim da lista: as fórmulas já estão prontas.
A3: Categoria | B3: Itens | C3: Valor total (R$) | D3: Devolvidos | E3: % devolvido | F3: Em aberto
A4: LogExpress | B4: =IF($A4="","",SUMIFS(tblBase[QTD],tblBase[Transportadora],$A4)) | C4: =IF($A4="","",SUMIFS(tblBase[Valor_Total],tblBase[Transportadora],$A4)) | D4: =IF($A4="","",SUMIFS(tblBase[QTD],tblBase[Transportadora],$A4,tblBase[Grupo_Status],"Concluído")) | E4: =IFERROR(D4/B4,"") | F4: =IF($A4="","",SUMIFS(tblBase[QTD],tblBase[Transportadora],$A4,tblBase[Grupo_Status],"Pendente")+SUMIFS(tblBase[QTD],tblBase[Transportadora],$A4,tblBase[Grupo_Status],"Em andamento"))
A5: TransNorte | B5: =IF($A5="","",SUMIFS(tblBase[QTD],tblBase[Transportadora],$A5)) | C5: =IF($A5="","",SUMIFS(tblBase[Valor_Total],tblBase[Transportadora],$A5)) | D5: =IF($A5="","",SUMIFS(tblBase[QTD],tblBase[Transportadora],$A5,tblBase[Grupo_Status],"Concluído")) | E5: =IFERROR(D5/B5,"") | F5: =IF($A5="","",SUMIFS(tblBase[QTD],tblBase[Transportadora],$A5,tblBase[Grupo_Status],"Pendente")+SUMIFS(tblBase[QTD],tblBase[Transportadora],$A5,tblBase[Grupo_Status],"Em andamento"))
A6: ViaCargo | B6: =IF($A6="","",SUMIFS(tblBase[QTD],tblBase[Transportadora],$A6)) | C6: =IF($A6="","",SUMIFS(tblBase[Valor_Total],tblBase[Transportadora],$A6)) | D6: =IF($A6="","",SUMIFS(tblBase[QTD],tblBase[Transportadora],$A6,tblBase[Grupo_Status],"Concluído")) | E6: =IFERROR(D6/B6,"") | F6: =IF($A6="","",SUMIFS(tblBase[QTD],tblBase[Transportadora],$A6,tblBase[Grupo_Status],"Pendente")+SUMIFS(tblBase[QTD],tblBase[Transportadora],$A6,tblBase[Grupo_Status],"Em andamento"))
A7: RotaSul | B7: =IF($A7="","",SUMIFS(tblBase[QTD],tblBase[Transportadora],$A7)) | C7: =IF($A7="","",SUMIFS(tblBase[Valor_Total],tblBase[Transportadora],$A7)) | D7: =IF($A7="","",SUMIFS(tblBase[QTD],tblBase[Transportadora],$A7,tblBase[Grupo_Status],"Concluído")) | E7: =IFERROR(D7/B7,"") | F7: =IF($A7="","",SUMIFS(tblBase[QTD],tblBase[Transportadora],$A7,tblBase[Grupo_Status],"Pendente")+SUMIFS(tblBase[QTD],tblBase[Transportadora],$A7,tblBase[Grupo_Status],"Em andamento"))
A8: CargoMax | B8: =IF($A8="","",SUMIFS(tblBase[QTD],tblBase[Transportadora],$A8)) | C8: =IF($A8="","",SUMIFS(tblBase[Valor_Total],tblBase[Transportadora],$A8)) | D8: =IF($A8="","",SUMIFS(tblBase[QTD],tblBase[Transportadora],$A8,tblBase[Grupo_Status],"Concluído")) | E8: =IFERROR(D8/B8,"") | F8: =IF($A8="","",SUMIFS(tblBase[QTD],tblBase[Transportadora],$A8,tblBase[Grupo_Status],"Pendente")+SUMIFS(tblBase[QTD],tblBase[Transportadora],$A8,tblBase[Grupo_Status],"Em andamento"))
A9: EntregaJá | B9: =IF($A9="","",SUMIFS(tblBase[QTD],tblBase[Transportadora],$A9)) | C9: =IF($A9="","",SUMIFS(tblBase[Valor_Total],tblBase[Transportadora],$A9)) | D9: =IF($A9="","",SUMIFS(tblBase[QTD],tblBase[Transportadora],$A9,tblBase[Grupo_Status],"Concluído")) | E9: =IFERROR(D9/B9,"") | F9: =IF($A9="","",SUMIFS(tblBase[QTD],tblBase[Transportadora],$A9,tblBase[Grupo_Status],"Pendente")+SUMIFS(tblBase[QTD],tblBase[Transportadora],$A9,tblBase[Grupo_Status],"Em andamento"))
B10: =IF($A10="","",SUMIFS(tblBase[QTD],tblBase[Transportadora],$A10)) | C10: =IF($A10="","",SUMIFS(tblBase[Valor_Total],tblBase[Transportadora],$A10)) | D10: =IF($A10="","",SUMIFS(tblBase[QTD],tblBase[Transportadora],$A10,tblBase[Grupo_Status],"Concluído")) | E10: =IFERROR(D10/B10,"") | F10: =IF($A10="","",SUMIFS(tblBase[QTD],tblBase[Transportadora],$A10,tblBase[Grupo_Status],"Pendente")+SUMIFS(tblBase[QTD],tblBase[Transportadora],$A10,tblBase[Grupo_Status],"Em andamento"))
B11: =IF($A11="","",SUMIFS(tblBase[QTD],tblBase[Transportadora],$A11)) | C11: =IF($A11="","",SUMIFS(tblBase[Valor_Total],tblBase[Transportadora],$A11)) | D11: =IF($A11="","",SUMIFS(tblBase[QTD],tblBase[Transportadora],$A11,tblBase[Grupo_Status],"Concluído")) | E11: =IFERROR(D11/B11,"") | F11: =IF($A11="","",SUMIFS(tblBase[QTD],tblBase[Transportadora],$A11,tblBase[Grupo_Status],"Pendente")+SUMIFS(tblBase[QTD],tblBase[Transportadora],$A11,tblBase[Grupo_Status],"Em andamento"))
B12: =IF($A12="","",SUMIFS(tblBase[QTD],tblBase[Transportadora],$A12)) | C12: =IF($A12="","",SUMIFS(tblBase[Valor_Total],tblBase[Transportadora],$A12)) | D12: =IF($A12="","",SUMIFS(tblBase[QTD],tblBase[Transportadora],$A12,tblBase[Grupo_Status],"Concluído")) | E12: =IFERROR(D12/B12,"") | F12: =IF($A12="","",SUMIFS(tblBase[QTD],tblBase[Transportadora],$A12,tblBase[Grupo_Status],"Pendente")+SUMIFS(tblBase[QTD],tblBase[Transportadora],$A12,tblBase[Grupo_Status],"Em andamento"))
B13: =IF($A13="","",SUMIFS(tblBase[QTD],tblBase[Transportadora],$A13)) | C13: =IF($A13="","",SUMIFS(tblBase[Valor_Total],tblBase[Transportadora],$A13)) | D13: =IF($A13="","",SUMIFS(tblBase[QTD],tblBase[Transportadora],$A13,tblBase[Grupo_Status],"Concluído")) | E13: =IFERROR(D13/B13,"") | F13: =IF($A13="","",SUMIFS(tblBase[QTD],tblBase[Transportadora],$A13,tblBase[Grupo_Status],"Pendente")+SUMIFS(tblBase[QTD],tblBase[Transportadora],$A13,tblBase[Grupo_Status],"Em andamento"))
B14: =IF($A14="","",SUMIFS(tblBase[QTD],tblBase[Transportadora],$A14)) | C14: =IF($A14="","",SUMIFS(tblBase[Valor_Total],tblBase[Transportadora],$A14)) | D14: =IF($A14="","",SUMIFS(tblBase[QTD],tblBase[Transportadora],$A14,tblBase[Grupo_Status],"Concluído")) | E14: =IFERROR(D14/B14,"") | F14: =IF($A14="","",SUMIFS(tblBase[QTD],tblBase[Transportadora],$A14,tblBase[Grupo_Status],"Pendente")+SUMIFS(tblBase[QTD],tblBase[Transportadora],$A14,tblBase[Grupo_Status],"Em andamento"))
B15: =IF($A15="","",SUMIFS(tblBase[QTD],tblBase[Transportadora],$A15)) | C15: =IF($A15="","",SUMIFS(tblBase[Valor_Total],tblBase[Transportadora],$A15)) | D15: =IF($A15="","",SUMIFS(tblBase[QTD],tblBase[Transportadora],$A15,tblBase[Grupo_Status],"Concluído")) | E15: =IFERROR(D15/B15,"") | F15: =IF($A15="","",SUMIFS(tblBase[QTD],tblBase[Transportadora],$A15,tblBase[Grupo_Status],"Pendente")+SUMIFS(tblBase[QTD],tblBase[Transportadora],$A15,tblBase[Grupo_Status],"Em andamento"))
B16: =IF($A16="","",SUMIFS(tblBase[QTD],tblBase[Transportadora],$A16)) | C16: =IF($A16="","",SUMIFS(tblBase[Valor_Total],tblBase[Transportadora],$A16)) | D16: =IF($A16="","",SUMIFS(tblBase[QTD],tblBase[Transportadora],$A16,tblBase[Grupo_Status],"Concluído")) | E16: =IFERROR(D16/B16,"") | F16: =IF($A16="","",SUMIFS(tblBase[QTD],tblBase[Transportadora],$A16,tblBase[Grupo_Status],"Pendente")+SUMIFS(tblBase[QTD],tblBase[Transportadora],$A16,tblBase[Grupo_Status],"Em andamento"))
B17: =IF($A17="","",SUMIFS(tblBase[QTD],tblBase[Transportadora],$A17)) | C17: =IF($A17="","",SUMIFS(tblBase[Valor_Total],tblBase[Transportadora],$A17)) | D17: =IF($A17="","",SUMIFS(tblBase[QTD],tblBase[Transportadora],$A17,tblBase[Grupo_Status],"Concluído")) | E17: =IFERROR(D17/B17,"") | F17: =IF($A17="","",SUMIFS(tblBase[QTD],tblBase[Transportadora],$A17,tblBase[Grupo_Status],"Pendente")+SUMIFS(tblBase[QTD],tblBase[Transportadora],$A17,tblBase[Grupo_Status],"Em andamento"))
B18: =IF($A18="","",SUMIFS(tblBase[QTD],tblBase[Transportadora],$A18)) | C18: =IF($A18="","",SUMIFS(tblBase[Valor_Total],tblBase[Transportadora],$A18)) | D18: =IF($A18="","",SUMIFS(tblBase[QTD],tblBase[Transportadora],$A18,tblBase[Grupo_Status],"Concluído")) | E18: =IFERROR(D18/B18,"") | F18: =IF($A18="","",SUMIFS(tblBase[QTD],tblBase[Transportadora],$A18,tblBase[Grupo_Status],"Pendente")+SUMIFS(tblBase[QTD],tblBase[Transportadora],$A18,tblBase[Grupo_Status],"Em andamento"))
B19: =IF($A19="","",SUMIFS(tblBase[QTD],tblBase[Transportadora],$A19)) | C19: =IF($A19="","",SUMIFS(tblBase[Valor_Total],tblBase[Transportadora],$A19)) | D19: =IF($A19="","",SUMIFS(tblBase[QTD],tblBase[Transportadora],$A19,tblBase[Grupo_Status],"Concluído")) | E19: =IFERROR(D19/B19,"") | F19: =IF($A19="","",SUMIFS(tblBase[QTD],tblBase[Transportadora],$A19,tblBase[Grupo_Status],"Pendente")+SUMIFS(tblBase[QTD],tblBase[Transportadora],$A19,tblBase[Grupo_Status],"Em andamento"))
B20: =IF($A20="","",SUMIFS(tblBase[QTD],tblBase[Transportadora],$A20)) | C20: =IF($A20="","",SUMIFS(tblBase[Valor_Total],tblBase[Transportadora],$A20)) | D20: =IF($A20="","",SUMIFS(tblBase[QTD],tblBase[Transportadora],$A20,tblBase[Grupo_Status],"Concluído")) | E20: =IFERROR(D20/B20,"") | F20: =IF($A20="","",SUMIFS(tblBase[QTD],tblBase[Transportadora],$A20,tblBase[Grupo_Status],"Pendente")+SUMIFS(tblBase[QTD],tblBase[Transportadora],$A20,tblBase[Grupo_Status],"Em andamento"))
B21: =IF($A21="","",SUMIFS(tblBase[QTD],tblBase[Transportadora],$A21)) | C21: =IF($A21="","",SUMIFS(tblBase[Valor_Total],tblBase[Transportadora],$A21)) | D21: =IF($A21="","",SUMIFS(tblBase[QTD],tblBase[Transportadora],$A21,tblBase[Grupo_Status],"Concluído")) | E21: =IFERROR(D21/B21,"") | F21: =IF($A21="","",SUMIFS(tblBase[QTD],tblBase[Transportadora],$A21,tblBase[Grupo_Status],"Pendente")+SUMIFS(tblBase[QTD],tblBase[Transportadora],$A21,tblBase[Grupo_Status],"Em andamento"))
... B25: =IF($A25="","",SUMIFS(tblBase[QTD],tblBase[Transportadora],$A25)) | C25: =IF($A25="","",SUMIFS(tblBase[Valor_Total],tblBase[Transportadora],$A25)) | D25: =IF($A25="","",SUMIFS(tblBase[QTD],tblBase[Transportadora],$A25,tblBase[Grupo_Status],"Concluído")) | E25: =IFERROR(D25/B25,"") | F25: =IF($A25="","",SUMIFS(tblBase[QTD],tblBase[Transportadora],$A25,tblBase[Grupo_Status],"Pendente")+SUMIFS(tblBase[QTD],tblBase[Transportadora],$A25,tblBase[Grupo_Status],"Em andamento"))
A26: Total da base | B26: =SUM(tblBase[QTD]) | C26: =SUM(tblBase[Valor_Total]) | D26: =SUMIFS(tblBase[QTD],tblBase[Grupo_Status],"Concluído") | E26: =IFERROR(D26/B26,"") | F26: =SUMIFS(tblBase[QTD],tblBase[Grupo_Status],"Pendente")+SUMIFS(tblBase[QTD],tblBase[Grupo_Status],"Em andamento")
A27: Não listado acima (categoria nova) | B27: =B26-SUM(B4:B25) | C27: =C26-SUM(C4:C25) | D27: =D26-SUM(D4:D25) | F27: =F26-SUM(F4:F25)

Sheet Resumo_Coordenador
A1: Desempenho por regional / coordenador
A2: Digite uma nova categoria nas linhas em branco no fim da lista: as fórmulas já estão prontas.
A3: Categoria | B3: Itens | C3: Valor total (R$) | D3: Devolvidos | E3: % devolvido | F3: Em aberto
A4: CENTRO OESTE | B4: =IF($A4="","",SUMIFS(tblBase[QTD],tblBase[Coordenador],$A4)) | C4: =IF($A4="","",SUMIFS(tblBase[Valor_Total],tblBase[Coordenador],$A4)) | D4: =IF($A4="","",SUMIFS(tblBase[QTD],tblBase[Coordenador],$A4,tblBase[Grupo_Status],"Concluído")) | E4: =IFERROR(D4/B4,"") | F4: =IF($A4="","",SUMIFS(tblBase[QTD],tblBase[Coordenador],$A4,tblBase[Grupo_Status],"Pendente")+SUMIFS(tblBase[QTD],tblBase[Coordenador],$A4,tblBase[Grupo_Status],"Em andamento"))
A5: NORDESTE | B5: =IF($A5="","",SUMIFS(tblBase[QTD],tblBase[Coordenador],$A5)) | C5: =IF($A5="","",SUMIFS(tblBase[Valor_Total],tblBase[Coordenador],$A5)) | D5: =IF($A5="","",SUMIFS(tblBase[QTD],tblBase[Coordenador],$A5,tblBase[Grupo_Status],"Concluído")) | E5: =IFERROR(D5/B5,"") | F5: =IF($A5="","",SUMIFS(tblBase[QTD],tblBase[Coordenador],$A5,tblBase[Grupo_Status],"Pendente")+SUMIFS(tblBase[QTD],tblBase[Coordenador],$A5,tblBase[Grupo_Status],"Em andamento"))
